<?xml version="1.0" ?>
<!-- =================================================================================== -->
<!-- |    This document was autogenerated by xacro from urdf/car3.xacro                | -->
<!-- |    EDITING THIS FILE BY HAND IS NOT RECOMMENDED                                 | -->
<!-- =================================================================================== -->
<robot xmlns:xacro="http://www.ros.org/wiki/xacro" name="car3">
  <material name="silver">
    <color rgba="0.700 0.700 0.700 1.000"/>
  </material>
  <transmission name="Revolute 1_tran">
    <type>transmission_interface/SimpleTransmission</type>
    <joint name="Revolute 1">
      <hardwareInterface>hardware_interface/EffortJointInterface</hardwareInterface>
    </joint>
    <actuator name="Revolute 1_actr">
      <hardwareInterface>hardware_interface/EffortJointInterface</hardwareInterface>
      <mechanicalReduction>1</mechanicalReduction>
    </actuator>
  </transmission>
  <transmission name="Revolute 2_tran">
    <type>transmission_interface/SimpleTransmission</type>
    <joint name="Revolute 2">
      <hardwareInterface>hardware_interface/EffortJointInterface</hardwareInterface>
    </joint>
    <actuator name="Revolute 2_actr">
      <hardwareInterface>hardware_interface/EffortJointInterface</hardwareInterface>
      <mechanicalReduction>1</mechanicalReduction>
    </actuator>
  </transmission>
  <transmission name="Revolute 3_tran">
    <type>transmission_interface/SimpleTransmission</type>
    <joint name="Revolute 3">
      <hardwareInterface>hardware_interface/EffortJointInterface</hardwareInterface>
    </joint>
    <actuator name="Revolute 3_actr">
      <hardwareInterface>hardware_interface/EffortJointInterface</hardwareInterface>
      <mechanicalReduction>1</mechanicalReduction>
    </actuator>
  </transmission>
  <transmission name="Revolute 4_tran">
    <type>transmission_interface/SimpleTransmission</type>
    <joint name="Revolute 4">
      <hardwareInterface>hardware_interface/EffortJointInterface</hardwareInterface>
    </joint>
    <actuator name="Revolute 4_actr">
      <hardwareInterface>hardware_interface/EffortJointInterface</hardwareInterface>
      <mechanicalReduction>1</mechanicalReduction>
    </actuator>
  </transmission>
  <gazebo>
    <plugin name="control" filename="libgazebo_ros_control.so"/>
  </gazebo>
  <gazebo reference="base_link">
    <material>Gazebo/Silver</material>
    <mu1>0.2</mu1>
    <mu2>0.2</mu2>
    <selfCollide>true</selfCollide>
    <gravity>true</gravity>
  </gazebo>
  <gazebo reference="rf_1">
    <material>Gazebo/Silver</material>
    <mu1>0.2</mu1>
    <mu2>0.2</mu2>
    <selfCollide>true</selfCollide>
  </gazebo>
  <gazebo reference="lb_1">
    <material>Gazebo/Silver</material>
    <mu1>0.2</mu1>
    <mu2>0.2</mu2>
    <selfCollide>true</selfCollide>
  </gazebo>
  <gazebo reference="lf_1">
    <material>Gazebo/Silver</material>
    <mu1>0.2</mu1>
    <mu2>0.2</mu2>
    <selfCollide>true</selfCollide>
  </gazebo>
  <gazebo reference="rb_1">
    <material>Gazebo/Silver</material>
    <mu1>0.2</mu1>
    <mu2>0.2</mu2>
    <selfCollide>true</selfCollide>
  </gazebo>
  <link name="base_link">
    <inertial>
      <origin xyz="0.0 2.0716135773123243e-05 0.025000000000000005" rpy="0 0 0"/>
      <mass value="15.89729201864544"/>
      <inertia ixx="0.056679" iyy="0.058003" izz="0.10813" ixy="0.0" iyz="0.0" ixz="0.0"/>
    </inertial>
    <visual>
      <origin xyz="0 0 0" rpy="0 0 0"/>
      <geometry>
        <mesh filename="package://car3_description/meshes/base_link.stl" scale="0.001 0.001 0.001"/>
      </geometry>
      <material name="silver"/>
    </visual>
    <collision>
      <origin xyz="0 0 0" rpy="0 0 0"/>
      <geometry>
        <mesh filename="package://car3_description/meshes/base_link.stl" scale="0.001 0.001 0.001"/>
      </geometry>
    </collision>
  </link>
  <link name="rf_1">
    <inertial>
      <origin xyz="0.010000000000000037 8.484561392352319e-08 -6.938893903907228e-18" rpy="0 0 0"/>
      <mass value="0.054688844913691116"/>
      <inertia ixx="4.4e-05" iyy="2.4e-05" izz="2.4e-05" ixy="0.0" iyz="-0.0" ixz="0.0"/>
    </inertial>
    <visual>
      <origin xyz="-0.12 0.071778 -0.025" rpy="0 0 0"/>
      <geometry>
        <mesh filename="package://car3_description/meshes/rf_1.stl" scale="0.001 0.001 0.001"/>
      </geometry>
      <material name="silver"/>
    </visual>
    <collision>
      <origin xyz="-0.12 0.071778 -0.025" rpy="0 0 0"/>
      <geometry>
        <mesh filename="package://car3_description/meshes/rf_1.stl" scale="0.001 0.001 0.001"/>
      </geometry>
    </collision>
  </link>
  <link name="lb_1">
    <inertial>
      <origin xyz="-0.010000000000000037 4.2283598547521173e-07 -6.938893903907228e-18" rpy="0 0 0"/>
      <mass value="0.054688844913691116"/>
      <inertia ixx="4.4e-05" iyy="2.4e-05" izz="2.4e-05" ixy="-0.0" iyz="-0.0" ixz="-0.0"/>
    </inertial>
    <visual>
      <origin xyz="0.12 -0.075116 -0.025" rpy="0 0 0"/>
      <geometry>
        <mesh filename="package://car3_description/meshes/lb_1.stl" scale="0.001 0.001 0.001"/>
      </geometry>
      <material name="silver"/>
    </visual>
    <collision>
      <origin xyz="0.12 -0.075116 -0.025" rpy="0 0 0"/>
      <geometry>
        <mesh filename="package://car3_description/meshes/lb_1.stl" scale="0.001 0.001 0.001"/>
      </geometry>
    </collision>
  </link>
  <link name="lf_1">
    <inertial>
      <origin xyz="-0.010000000000000037 8.484561392352319e-08 -6.938893903907228e-18" rpy="0 0 0"/>
      <mass value="0.054688844913691116"/>
      <inertia ixx="4.4e-05" iyy="2.4e-05" izz="2.4e-05" ixy="0.0" iyz="-0.0" ixz="-0.0"/>
    </inertial>
    <visual>
      <origin xyz="0.12 0.071778 -0.025" rpy="0 0 0"/>
      <geometry>
        <mesh filename="package://car3_description/meshes/lf_1.stl" scale="0.001 0.001 0.001"/>
      </geometry>
      <material name="silver"/>
    </visual>
    <collision>
      <origin xyz="0.12 0.071778 -0.025" rpy="0 0 0"/>
      <geometry>
        <mesh filename="package://car3_description/meshes/lf_1.stl" scale="0.001 0.001 0.001"/>
      </geometry>
    </collision>
  </link>
  <link name="rb_1">
    <inertial>
      <origin xyz="0.010000000000000037 4.2283598547521173e-07 -6.938893903907228e-18" rpy="0 0 0"/>
      <mass value="0.054688844913691116"/>
      <inertia ixx="4.4e-05" iyy="2.4e-05" izz="2.4e-05" ixy="0.0" iyz="-0.0" ixz="0.0"/>
    </inertial>
    <visual>
      <origin xyz="-0.12 -0.075116 -0.025" rpy="0 0 0"/>
      <geometry>
        <mesh filename="package://car3_description/meshes/rb_1.stl" scale="0.001 0.001 0.001"/>
      </geometry>
      <material name="silver"/>
    </visual>
    <collision>
      <origin xyz="-0.12 -0.075116 -0.025" rpy="0 0 0"/>
      <geometry>
        <mesh filename="package://car3_description/meshes/rb_1.stl" scale="0.001 0.001 0.001"/>
      </geometry>
    </collision>
  </link>
  <joint name="Revolute 1" type="continuous">
    <origin xyz="0.12 -0.071778 0.025" rpy="0 0 0"/>
    <parent link="base_link"/>
    <child link="rf_1"/>
    <axis xyz="1.0 0.0 0.0"/>
  </joint>
  <joint name="Revolute 2" type="continuous">
    <origin xyz="-0.12 0.075116 0.025" rpy="0 0 0"/>
    <parent link="base_link"/>
    <child link="lb_1"/>
    <axis xyz="-1.0 0.0 0.0"/>
  </joint>
  <joint name="Revolute 3" type="continuous">
    <origin xyz="-0.12 -0.071778 0.025" rpy="0 0 0"/>
    <parent link="base_link"/>
    <child link="lf_1"/>
    <axis xyz="-1.0 0.0 0.0"/>
  </joint>
  <joint name="Revolute 4" type="continuous">
    <origin xyz="0.12 0.075116 0.025" rpy="0 0 0"/>
    <parent link="base_link"/>
    <child link="rb_1"/>
    <axis xyz="1.0 0.0 0.0"/>
  </joint>
</robot>
